<mujoco model="serialleg_closed_chain_v3_train_obb_trim">
  <compiler angle="radian" meshdir="meshes" autolimits="true" strippath="false" />
  <option timestep="0.005" solver="Newton" cone="pyramidal" integrator="implicitfast" iterations="100" />
  <visual>
    <global offwidth="1280" offheight="720" />
  </visual>
  <default>
    <geom solref="0.010 1.5" solimp="0.85 0.99 0.005" />
    <joint damping="0" />
    <equality solref="0.010 1.05" solimp="0.2 0.95 0.002 0.9 6" />
  </default>
  <asset>
    <texture name="grid" type="2d" builtin="checker" width="512" height="512" rgb1=".1 .2 .3" rgb2=".2 .3 .4" />
    <material name="grid" texture="grid" texrepeat="1 1" texuniform="true" reflectance=".2" />
    <mesh name="visual_swbase_base_link_00" file="web_visual/base/base_link_chunk_00.stl" />
    <mesh name="visual_swbase_base_link_01" file="web_visual/base/base_link_chunk_01.stl" />
    <mesh name="visual_swbase_base_link_02" file="web_visual/base/base_link_chunk_02.stl" />
    <mesh name="visual_swbase_base_link_03" file="web_visual/base/base_link_chunk_03.stl" />
    <mesh name="visual_swbase_base_link_04" file="web_visual/base/base_link_chunk_04.stl" />
    <mesh name="visual_swbase_base_link_05" file="web_visual/base/base_link_chunk_05.stl" />
    <mesh name="visual_swbase_base_link_06" file="web_visual/base/base_link_chunk_06.stl" />
    <mesh name="visual_swbase_base_link_07" file="web_visual/base/base_link_chunk_07.stl" />
    <mesh name="visual_swbase_base_link_08" file="web_visual/base/base_link_chunk_08.stl" />
    <mesh name="visual_swbase_base_link_09" file="web_visual/base/base_link_chunk_09.stl" />
    <mesh name="visual_swbase_base_link_10" file="web_visual/base/base_link_chunk_10.stl" />
    <mesh name="visual_swbase_base_link_11" file="web_visual/base/base_link_chunk_11.stl" />
    <mesh name="visual_swbase_base_link_12" file="web_visual/base/base_link_chunk_12.stl" />
    <mesh name="visual_lf_wheel" file="web_visual/links/lf_wheel_link.STL" />
    <mesh name="visual_rf_wheel" file="web_visual/links/rf_wheel_link.STL" />
    <mesh name="visual_lf_thigh" file="web_visual/links/lf_thigh_link.STL" />
    <mesh name="visual_l_drive_bar" file="web_visual/links/lf_calf_1_link.STL" />
    <mesh name="visual_l_coupler" file="web_visual/links/lf_calf_2_link.STL" />
    <mesh name="visual_l_calf" file="web_visual/links/lf_calf_3_link.STL" />
    <mesh name="visual_rf_thigh" file="web_visual/links/rf_thigh_link.STL" />
    <mesh name="visual_r_drive_bar" file="web_visual/links/rf_calf_1_link.STL" />
    <mesh name="visual_r_coupler" file="web_visual/links/rf_calf_2_link.STL" />
    <mesh name="visual_r_calf" file="web_visual/links/rf_calf_3_link.STL" />
    <mesh name="stair_base_visual_coacd_mesh_00" file="stair_base_visual_coacd_32/base_visual_coacd_part_00.stl" />
    <mesh name="stair_base_visual_coacd_mesh_01" file="stair_base_visual_coacd_32/base_visual_coacd_part_01.stl" />
    <mesh name="stair_base_visual_coacd_mesh_02" file="stair_base_visual_coacd_32/base_visual_coacd_part_02.stl" />
    <mesh name="stair_base_visual_coacd_mesh_03" file="stair_base_visual_coacd_32/base_visual_coacd_part_03.stl" />
    <mesh name="stair_base_visual_coacd_mesh_04" file="stair_base_visual_coacd_32/base_visual_coacd_part_04.stl" />
    <mesh name="stair_base_visual_coacd_mesh_05" file="stair_base_visual_coacd_32/base_visual_coacd_part_05.stl" />
    <mesh name="stair_base_visual_coacd_mesh_06" file="stair_base_visual_coacd_32/base_visual_coacd_part_06.stl" />
    <mesh name="stair_base_visual_coacd_mesh_07" file="stair_base_visual_coacd_32/base_visual_coacd_part_07.stl" />
    <mesh name="stair_base_visual_coacd_mesh_08" file="stair_base_visual_coacd_32/base_visual_coacd_part_08.stl" />
    <mesh name="stair_base_visual_coacd_mesh_09" file="stair_base_visual_coacd_32/base_visual_coacd_part_09.stl" />
    <mesh name="stair_base_visual_coacd_mesh_10" file="stair_base_visual_coacd_32/base_visual_coacd_part_10.stl" />
    <mesh name="stair_base_visual_coacd_mesh_11" file="stair_base_visual_coacd_32/base_visual_coacd_part_11.stl" />
    <mesh name="stair_base_visual_coacd_mesh_12" file="stair_base_visual_coacd_32/base_visual_coacd_part_12.stl" />
    <mesh name="stair_base_visual_coacd_mesh_13" file="stair_base_visual_coacd_32/base_visual_coacd_part_13.stl" />
    <mesh name="stair_base_visual_coacd_mesh_14" file="stair_base_visual_coacd_32/base_visual_coacd_part_14.stl" />
    <mesh name="stair_base_visual_coacd_mesh_15" file="stair_base_visual_coacd_32/base_visual_coacd_part_15.stl" />
    <mesh name="stair_base_visual_coacd_mesh_16" file="stair_base_visual_coacd_32/base_visual_coacd_part_16.stl" />
    <mesh name="stair_base_visual_coacd_mesh_17" file="stair_base_visual_coacd_32/base_visual_coacd_part_17.stl" />
    <mesh name="stair_base_visual_coacd_mesh_18" file="stair_base_visual_coacd_32/base_visual_coacd_part_18.stl" />
    <mesh name="stair_base_visual_coacd_mesh_19" file="stair_base_visual_coacd_32/base_visual_coacd_part_19.stl" />
    <mesh name="stair_base_visual_coacd_mesh_20" file="stair_base_visual_coacd_32/base_visual_coacd_part_20.stl" />
    <mesh name="stair_base_visual_coacd_mesh_21" file="stair_base_visual_coacd_32/base_visual_coacd_part_21.stl" />
    <mesh name="stair_base_visual_coacd_mesh_22" file="stair_base_visual_coacd_32/base_visual_coacd_part_22.stl" />
    <mesh name="stair_base_visual_coacd_mesh_23" file="stair_base_visual_coacd_32/base_visual_coacd_part_23.stl" />
    <mesh name="stair_base_visual_coacd_mesh_24" file="stair_base_visual_coacd_32/base_visual_coacd_part_24.stl" />
    <mesh name="stair_base_visual_coacd_mesh_25" file="stair_base_visual_coacd_32/base_visual_coacd_part_25.stl" />
    <mesh name="stair_base_visual_coacd_mesh_26" file="stair_base_visual_coacd_32/base_visual_coacd_part_26.stl" />
    <mesh name="stair_base_visual_coacd_mesh_27" file="stair_base_visual_coacd_32/base_visual_coacd_part_27.stl" />
    <mesh name="stair_base_visual_coacd_mesh_28" file="stair_base_visual_coacd_32/base_visual_coacd_part_28.stl" />
    <mesh name="stair_base_visual_coacd_mesh_29" file="stair_base_visual_coacd_32/base_visual_coacd_part_29.stl" />
    <mesh name="stair_base_visual_coacd_mesh_30" file="stair_base_visual_coacd_32/base_visual_coacd_part_30.stl" />
    <mesh name="stair_base_visual_coacd_mesh_31" file="stair_base_visual_coacd_32/base_visual_coacd_part_31.stl" />
    <mesh name="staircol_lf0_Link_00" file="sw_collision_v3/lf0_Link/lf0_Link_sw_env_00.stl" />
    <mesh name="staircol_lf0_Link_01" file="sw_collision_v3/lf0_Link/lf0_Link_sw_env_01.stl" />
    <mesh name="staircol_rf0_Link_00" file="sw_collision_v3/rf0_Link/rf0_Link_sw_env_00.stl" />
    <mesh name="staircol_rf0_Link_01" file="sw_collision_v3/rf0_Link/rf0_Link_sw_env_01.stl" />
    <mesh name="staircol_lf1_Link_00" file="sw_collision_v3/lf1_Link/lf1_Link_sw_env_00.stl" />
    <mesh name="staircol_rf1_Link_00" file="sw_collision_v3/rf1_Link/rf1_Link_sw_env_00.stl" />
    <mesh name="legcoacd_l_drive_bar_Link_00" file="leg_coacd_v1/l_drive_bar_Link/l_drive_bar_Link_coacd_00.stl" />
    <mesh name="legcoacd_l_drive_bar_Link_01" file="leg_coacd_v1/l_drive_bar_Link/l_drive_bar_Link_coacd_01.stl" />
    <mesh name="legcoacd_l_drive_bar_Link_02" file="leg_coacd_v1/l_drive_bar_Link/l_drive_bar_Link_coacd_02.stl" />
    <mesh name="legcoacd_l_drive_bar_Link_03" file="leg_coacd_v1/l_drive_bar_Link/l_drive_bar_Link_coacd_03.stl" />
    <mesh name="legcoacd_l_coupler_Link_00" file="leg_coacd_v1/l_coupler_Link/l_coupler_Link_coacd_00.stl" />
    <mesh name="legcoacd_l_coupler_Link_01" file="leg_coacd_v1/l_coupler_Link/l_coupler_Link_coacd_01.stl" />
    <mesh name="legcoacd_l_coupler_Link_02" file="leg_coacd_v1/l_coupler_Link/l_coupler_Link_coacd_02.stl" />
    <mesh name="legcoacd_l_coupler_Link_03" file="leg_coacd_v1/l_coupler_Link/l_coupler_Link_coacd_03.stl" />
    <mesh name="legcoacd_r_drive_bar_Link_00" file="leg_coacd_v1/r_drive_bar_Link/r_drive_bar_Link_coacd_00.stl" />
    <mesh name="legcoacd_r_drive_bar_Link_01" file="leg_coacd_v1/r_drive_bar_Link/r_drive_bar_Link_coacd_01.stl" />
    <mesh name="legcoacd_r_drive_bar_Link_02" file="leg_coacd_v1/r_drive_bar_Link/r_drive_bar_Link_coacd_02.stl" />
    <mesh name="legcoacd_r_drive_bar_Link_03" file="leg_coacd_v1/r_drive_bar_Link/r_drive_bar_Link_coacd_03.stl" />
    <mesh name="legcoacd_r_coupler_Link_00" file="leg_coacd_v1/r_coupler_Link/r_coupler_Link_coacd_00.stl" />
    <mesh name="legcoacd_r_coupler_Link_01" file="leg_coacd_v1/r_coupler_Link/r_coupler_Link_coacd_01.stl" />
    <mesh name="legcoacd_r_coupler_Link_02" file="leg_coacd_v1/r_coupler_Link/r_coupler_Link_coacd_02.stl" />
    <mesh name="legcoacd_r_coupler_Link_03" file="leg_coacd_v1/r_coupler_Link/r_coupler_Link_coacd_03.stl" />
  </asset>
  <worldbody>
    <geom name="floor" type="plane" size="0 0 .05" material="grid" friction="0.8 0.005 0.0001" contype="2" conaffinity="1" />
    <light name="spotlight" mode="targetbodycom" target="base_link" diffuse=".8 .8 .8" specular="0.3 0.3 0.3" pos="0 -6 4" cutoff="30" />
    <body name="base_link" pos="0 0 0.22">
      <freejoint />
      <inertial pos="-0.01780372 0.01307697 -0.03342401" mass="10.74541262" fullinertia="0.14395729 0.21248062 0.30929562 -0.00229101 0.00807199 -0.00039793" />
      <geom name="base_link_sw_raw_visual_00" type="mesh" mesh="visual_swbase_base_link_00" contype="0" conaffinity="0" group="1" />
      <geom name="base_link_sw_raw_visual_01" type="mesh" mesh="visual_swbase_base_link_01" contype="0" conaffinity="0" group="1" />
      <geom name="base_link_sw_raw_visual_02" type="mesh" mesh="visual_swbase_base_link_02" contype="0" conaffinity="0" group="1" />
      <geom name="base_link_sw_raw_visual_03" type="mesh" mesh="visual_swbase_base_link_03" contype="0" conaffinity="0" group="1" />
      <geom name="base_link_sw_raw_visual_04" type="mesh" mesh="visual_swbase_base_link_04" contype="0" conaffinity="0" group="1" />
      <geom name="base_link_sw_raw_visual_05" type="mesh" mesh="visual_swbase_base_link_05" contype="0" conaffinity="0" group="1" />
      <geom name="base_link_sw_raw_visual_06" type="mesh" mesh="visual_swbase_base_link_06" contype="0" conaffinity="0" group="1" />
      <geom name="base_link_sw_raw_visual_07" type="mesh" mesh="visual_swbase_base_link_07" contype="0" conaffinity="0" group="1" />
      <geom name="base_link_sw_raw_visual_08" type="mesh" mesh="visual_swbase_base_link_08" contype="0" conaffinity="0" group="1" />
      <geom name="base_link_sw_raw_visual_09" type="mesh" mesh="visual_swbase_base_link_09" contype="0" conaffinity="0" group="1" />
      <geom name="base_link_sw_raw_visual_10" type="mesh" mesh="visual_swbase_base_link_10" contype="0" conaffinity="0" group="1" />
      <geom name="base_link_sw_raw_visual_11" type="mesh" mesh="visual_swbase_base_link_11" contype="0" conaffinity="0" group="1" />
      <geom name="base_link_sw_raw_visual_12" type="mesh" mesh="visual_swbase_base_link_12" contype="0" conaffinity="0" group="1" />
      <geom name="base_link_collision_visual_coacd_00" type="mesh" mesh="stair_base_visual_coacd_mesh_00" group="0" contype="1" conaffinity="2" friction="0.8 0.005 0.0001" rgba="0.05 0.65 1.0 0.40" />
      <geom name="base_link_collision_visual_coacd_01" type="mesh" mesh="stair_base_visual_coacd_mesh_01" group="0" contype="1" conaffinity="2" friction="0.8 0.005 0.0001" rgba="0.05 0.65 1.0 0.40" />
      <geom name="base_link_collision_visual_coacd_02" type="mesh" mesh="stair_base_visual_coacd_mesh_02" group="0" contype="1" conaffinity="2" friction="0.8 0.005 0.0001" rgba="0.05 0.65 1.0 0.40" />
      <geom name="base_link_collision_visual_coacd_03" type="mesh" mesh="stair_base_visual_coacd_mesh_03" group="0" contype="1" conaffinity="2" friction="0.8 0.005 0.0001" rgba="0.05 0.65 1.0 0.40" />
      <geom name="base_link_collision_visual_coacd_04" type="mesh" mesh="stair_base_visual_coacd_mesh_04" group="0" contype="1" conaffinity="2" friction="0.8 0.005 0.0001" rgba="0.05 0.65 1.0 0.40" />
      <geom name="base_link_collision_visual_coacd_05" type="mesh" mesh="stair_base_visual_coacd_mesh_05" group="0" contype="1" conaffinity="2" friction="0.8 0.005 0.0001" rgba="0.05 0.65 1.0 0.40" />
      <geom name="base_link_collision_visual_coacd_06" type="mesh" mesh="stair_base_visual_coacd_mesh_06" group="0" contype="1" conaffinity="2" friction="0.8 0.005 0.0001" rgba="0.05 0.65 1.0 0.40" />
      <geom name="base_link_collision_visual_coacd_07" type="mesh" mesh="stair_base_visual_coacd_mesh_07" group="0" contype="1" conaffinity="2" friction="0.8 0.005 0.0001" rgba="0.05 0.65 1.0 0.40" />
      <geom name="base_link_collision_visual_coacd_08" type="mesh" mesh="stair_base_visual_coacd_mesh_08" group="0" contype="1" conaffinity="2" friction="0.8 0.005 0.0001" rgba="0.05 0.65 1.0 0.40" />
      <geom name="base_link_collision_visual_coacd_09" type="mesh" mesh="stair_base_visual_coacd_mesh_09" group="0" contype="1" conaffinity="2" friction="0.8 0.005 0.0001" rgba="0.05 0.65 1.0 0.40" />
      <geom name="base_link_collision_visual_coacd_10" type="mesh" mesh="stair_base_visual_coacd_mesh_10" group="0" contype="1" conaffinity="2" friction="0.8 0.005 0.0001" rgba="0.05 0.65 1.0 0.40" />
      <geom name="base_link_collision_visual_coacd_11" type="mesh" mesh="stair_base_visual_coacd_mesh_11" group="0" contype="1" conaffinity="2" friction="0.8 0.005 0.0001" rgba="0.05 0.65 1.0 0.40" />
      <geom name="base_link_collision_visual_coacd_12" type="mesh" mesh="stair_base_visual_coacd_mesh_12" group="0" contype="1" conaffinity="2" friction="0.8 0.005 0.0001" rgba="0.05 0.65 1.0 0.40" />
      <geom name="base_link_collision_visual_coacd_13" type="mesh" mesh="stair_base_visual_coacd_mesh_13" group="0" contype="1" conaffinity="2" friction="0.8 0.005 0.0001" rgba="0.05 0.65 1.0 0.40" />
      <geom name="base_link_collision_visual_coacd_14" type="mesh" mesh="stair_base_visual_coacd_mesh_14" group="0" contype="1" conaffinity="2" friction="0.8 0.005 0.0001" rgba="0.05 0.65 1.0 0.40" />
      <geom name="base_link_collision_visual_coacd_15" type="mesh" mesh="stair_base_visual_coacd_mesh_15" group="0" contype="1" conaffinity="2" friction="0.8 0.005 0.0001" rgba="0.05 0.65 1.0 0.40" />
      <geom name="base_link_collision_visual_coacd_16" type="mesh" mesh="stair_base_visual_coacd_mesh_16" group="0" contype="1" conaffinity="2" friction="0.8 0.005 0.0001" rgba="0.05 0.65 1.0 0.40" />
      <geom name="base_link_collision_visual_coacd_17" type="mesh" mesh="stair_base_visual_coacd_mesh_17" group="0" contype="1" conaffinity="2" friction="0.8 0.005 0.0001" rgba="0.05 0.65 1.0 0.40" />
      <geom name="base_link_collision_visual_coacd_18" type="mesh" mesh="stair_base_visual_coacd_mesh_18" group="0" contype="1" conaffinity="2" friction="0.8 0.005 0.0001" rgba="0.05 0.65 1.0 0.40" />
      <geom name="base_link_collision_visual_coacd_19" type="mesh" mesh="stair_base_visual_coacd_mesh_19" group="0" contype="1" conaffinity="2" friction="0.8 0.005 0.0001" rgba="0.05 0.65 1.0 0.40" />
      <geom name="base_link_collision_visual_coacd_20" type="mesh" mesh="stair_base_visual_coacd_mesh_20" group="0" contype="1" conaffinity="2" friction="0.8 0.005 0.0001" rgba="0.05 0.65 1.0 0.40" />
      <geom name="base_link_collision_visual_coacd_21" type="mesh" mesh="stair_base_visual_coacd_mesh_21" group="0" contype="1" conaffinity="2" friction="0.8 0.005 0.0001" rgba="0.05 0.65 1.0 0.40" />
      <geom name="base_link_collision_visual_coacd_22" type="mesh" mesh="stair_base_visual_coacd_mesh_22" group="0" contype="1" conaffinity="2" friction="0.8 0.005 0.0001" rgba="0.05 0.65 1.0 0.40" />
      <geom name="base_link_collision_visual_coacd_23" type="mesh" mesh="stair_base_visual_coacd_mesh_23" group="0" contype="1" conaffinity="2" friction="0.8 0.005 0.0001" rgba="0.05 0.65 1.0 0.40" />
      <geom name="base_link_collision_visual_coacd_24" type="mesh" mesh="stair_base_visual_coacd_mesh_24" group="0" contype="1" conaffinity="2" friction="0.8 0.005 0.0001" rgba="0.05 0.65 1.0 0.40" />
      <geom name="base_link_collision_visual_coacd_25" type="mesh" mesh="stair_base_visual_coacd_mesh_25" group="0" contype="1" conaffinity="2" friction="0.8 0.005 0.0001" rgba="0.05 0.65 1.0 0.40" />
      <geom name="base_link_collision_visual_coacd_26" type="mesh" mesh="stair_base_visual_coacd_mesh_26" group="0" contype="1" conaffinity="2" friction="0.8 0.005 0.0001" rgba="0.05 0.65 1.0 0.40" />
      <geom name="base_link_collision_visual_coacd_27" type="mesh" mesh="stair_base_visual_coacd_mesh_27" group="0" contype="1" conaffinity="2" friction="0.8 0.005 0.0001" rgba="0.05 0.65 1.0 0.40" />
      <geom name="base_link_collision_visual_coacd_28" type="mesh" mesh="stair_base_visual_coacd_mesh_28" group="0" contype="1" conaffinity="2" friction="0.8 0.005 0.0001" rgba="0.05 0.65 1.0 0.40" />
      <geom name="base_link_collision_visual_coacd_29" type="mesh" mesh="stair_base_visual_coacd_mesh_29" group="0" contype="1" conaffinity="2" friction="0.8 0.005 0.0001" rgba="0.05 0.65 1.0 0.40" />
      <geom name="base_link_collision_visual_coacd_30" type="mesh" mesh="stair_base_visual_coacd_mesh_30" group="0" contype="1" conaffinity="2" friction="0.8 0.005 0.0001" rgba="0.05 0.65 1.0 0.40" />
      <geom name="base_link_collision_visual_coacd_31" type="mesh" mesh="stair_base_visual_coacd_mesh_31" group="0" contype="1" conaffinity="2" friction="0.8 0.005 0.0001" rgba="0.05 0.65 1.0 0.40" />
      <body name="lf0_Link" pos="0 0.16885 0">
        <joint name="lf0_Joint" type="hinge" axis="0 1 0" armature="0.01" />
        <inertial pos="-0.09968276 0.00404879 0.00282013" mass="0.32242010" fullinertia="0.00013496 0.00177872 0.00170006 0.00007976 0.00009393 -0.00000238" />
        <geom name="lf0_Link_visual" type="mesh" mesh="visual_lf_thigh" contype="0" conaffinity="0" group="1" />
        <site name="lf_thigh_end" pos="-0.17993464 0.0215 0.00489576" size="0.008" rgba="1 0 0 1" />
        <site name="l_spring_p1" pos="0.00705 0.00497702 -0.04678497" group="4" />
        <geom name="lf0_Link_stair_col_00" mesh="staircol_lf0_Link_00" type="mesh" group="0" contype="1" conaffinity="2" />
        <geom name="lf0_Link_stair_col_01" mesh="staircol_lf0_Link_01" type="mesh" group="0" contype="1" conaffinity="2" />
        <body name="lf1_Link" pos="-0.12990117 0.0215 0.04639203">
          <joint name="lf1_Joint" type="hinge" pos="-0.05003347 0 -0.04149627" axis="0 1 0" damping="1" armature="0.02" />
          <inertial pos="-0.04177153 -0.00094144 -0.06569666" mass="0.32184046" fullinertia="0.00126318 0.00185755 0.00061944 0.00000296 -0.00076497 0.00001136" />
          <geom name="lf1_Link_visual" type="mesh" mesh="visual_l_calf" contype="0" conaffinity="0" group="1" />
          <site name="lf_calf_closure" pos="-0.05003347 0 -0.04149627" size="0.008" rgba="0 1 0 1" />
          <site name="lf_coupler_closure" pos="0 0 0" size="0.008" rgba="0 0.7 1 1" />
          <site name="l_spring_p2" pos="-0.09034883 -0.01652298 -0.09317700" group="4" />
          <geom name="lf1_Link_stair_col_00" mesh="staircol_lf1_Link_00" type="mesh" group="0" contype="1" conaffinity="2" />
          <body name="l_wheel_Link" pos="-0.15699 0.02705 -0.21049">
            <joint name="l_wheel_Joint" type="hinge" axis="0 1 0" armature="0.005" />
            <inertial pos="-0.00007447 -0.00660229 -0.00008940" mass="0.27783378" fullinertia="0.00026503 0.00048080 0.00026516 -0.00000020 0.00000031 -0.00000025" />
            <geom type="mesh" mesh="visual_lf_wheel" pos="0 0 0" name="l_wheel_Link_visual" contype="0" conaffinity="0" group="1" />
            <geom name="l_wheel_Link_collision_0" type="cylinder" size="0.060 0.010" pos="0.000069 -0.006500 -0.000029" euler="1.5708 0 0" group="0" contype="1" conaffinity="2" friction="0.8 0.005 0.0001" />
          </body>
        </body>
      </body>
      <body name="l_drive_bar_Link" pos="0 0.16885 0">
        <joint name="l_drive_bar_Joint" type="hinge" axis="0 1 0" armature="0.01" />
        <inertial pos="0.01185501 0.01367042 0.01339557" mass="0.04635322" fullinertia="0.00002217 0.00004090 0.00001928 -0.00000004 -0.00001180 -0.00000005" />
        <geom name="l_drive_bar_Link_visual" type="mesh" mesh="visual_l_drive_bar" contype="0" conaffinity="0" group="1" />
        <geom name="l_drive_bar_Link_coacd_col_00" mesh="legcoacd_l_drive_bar_Link_00" type="mesh" group="0" contype="1" conaffinity="2" />
        <geom name="l_drive_bar_Link_coacd_col_01" mesh="legcoacd_l_drive_bar_Link_01" type="mesh" group="0" contype="1" conaffinity="2" />
        <geom name="l_drive_bar_Link_coacd_col_02" mesh="legcoacd_l_drive_bar_Link_02" type="mesh" group="0" contype="1" conaffinity="2" />
        <geom name="l_drive_bar_Link_coacd_col_03" mesh="legcoacd_l_drive_bar_Link_03" type="mesh" group="0" contype="1" conaffinity="2" />
        <body name="l_coupler_Link" pos="0.04009536 0.00690000 0.04530576">
          <joint name="l_coupler_Joint" type="hinge" axis="0 1 0" damping="1" armature="0.02" />
          <inertial pos="-0.08300337 0.00146519 0.01330427" mass="0.02321892" fullinertia="0.00000249 0.00007107 0.00006893 0.00000032 -0.00000125 -0.00000007" />
          <geom name="l_coupler_Link_visual" type="mesh" mesh="visual_l_coupler" contype="0" conaffinity="0" group="1" />
          <site name="l_coupler_end" pos="-0.16999653 0.0146 0.00108627" size="0.008" rgba="1 0.5 0 1" />
          <geom name="l_coupler_Link_coacd_col_00" mesh="legcoacd_l_coupler_Link_00" type="mesh" group="0" contype="1" conaffinity="2" />
          <geom name="l_coupler_Link_coacd_col_01" mesh="legcoacd_l_coupler_Link_01" type="mesh" group="0" contype="1" conaffinity="2" />
          <geom name="l_coupler_Link_coacd_col_02" mesh="legcoacd_l_coupler_Link_02" type="mesh" group="0" contype="1" conaffinity="2" />
          <geom name="l_coupler_Link_coacd_col_03" mesh="legcoacd_l_coupler_Link_03" type="mesh" group="0" contype="1" conaffinity="2" />
        </body>
      </body>
      <body name="rf0_Link" pos="0 -0.16885 0">
        <joint name="rf0_Joint" type="hinge" axis="0 -1 0" armature="0.01" />
        <inertial pos="-0.09968276 -0.00404879 0.00282013" mass="0.32242010" fullinertia="0.00013496 0.00177872 0.00170006 -0.00007976 0.00009393 0.00000238" />
        <geom name="rf0_Link_visual" type="mesh" mesh="visual_rf_thigh" contype="0" conaffinity="0" group="1" />
        <site name="rf_thigh_end" pos="-0.179935 -0.0200 0.004896" size="0.008" rgba="1 0 0 1" />
        <site name="r_spring_p1" pos="0.00705 -0.00497702 -0.04678497" group="4" />
        <geom name="rf0_Link_stair_col_00" mesh="staircol_rf0_Link_00" type="mesh" group="0" contype="1" conaffinity="2" />
        <geom name="rf0_Link_stair_col_01" mesh="staircol_rf0_Link_01" type="mesh" group="0" contype="1" conaffinity="2" />
        <body name="rf1_Link" pos="-0.12990153 -0.0200 0.04639227">
          <joint name="rf1_Joint" type="hinge" pos="-0.05003347 0 -0.04149627" axis="0 -1 0" damping="1" armature="0.02" />
          <inertial pos="-0.04177153 0.00094144 -0.06569666" mass="0.32184046" fullinertia="0.00126318 0.00185755 0.00061944 -0.00000296 -0.00076497 -0.00001136" />
          <geom name="rf1_Link_visual" type="mesh" mesh="visual_r_calf" contype="0" conaffinity="0" group="1" />
          <site name="rf_calf_closure" pos="-0.05003347 0 -0.04149627" size="0.008" rgba="0 1 0 1" />
          <site name="rf_coupler_closure" pos="0 0 0" size="0.008" rgba="0 0.7 1 1" />
          <site name="r_spring_p2" pos="-0.09034883 0.01502298 -0.09317700" group="4" />
          <geom name="rf1_Link_stair_col_00" mesh="staircol_rf1_Link_00" type="mesh" group="0" contype="1" conaffinity="2" />
          <body name="r_wheel_Link" pos="-0.15699 -0.02705 -0.21049">
            <joint name="r_wheel_Joint" type="hinge" axis="0 -1 0" armature="0.005" />
            <inertial pos="-0.00007447 0.00660229 -0.00008940" mass="0.27783378" fullinertia="0.00026503 0.00048080 0.00026516 0.00000020 0.00000031 0.00000025" />
            <geom type="mesh" mesh="visual_rf_wheel" pos="0 0 0" name="r_wheel_Link_visual" contype="0" conaffinity="0" group="1" />
            <geom name="r_wheel_Link_collision_0" type="cylinder" size="0.060 0.010" pos="-0.000069 0.006500 0.000029" euler="1.5708 0 0" group="0" contype="1" conaffinity="2" friction="0.8 0.005 0.0001" />
          </body>
        </body>
      </body>
      <body name="r_drive_bar_Link" pos="0 -0.16885 0">
        <joint name="r_drive_bar_Joint" type="hinge" axis="0 -1 0" armature="0.01" />
        <inertial pos="0.01185501 -0.01367042 0.01339557" mass="0.04635322" fullinertia="0.00002217 0.00004090 0.00001928 0.00000004 -0.00001180 0.00000005" />
        <geom name="r_drive_bar_Link_visual" type="mesh" mesh="visual_r_drive_bar" contype="0" conaffinity="0" group="1" />
        <geom name="r_drive_bar_Link_coacd_col_00" mesh="legcoacd_r_drive_bar_Link_00" type="mesh" group="0" contype="1" conaffinity="2" />
        <geom name="r_drive_bar_Link_coacd_col_01" mesh="legcoacd_r_drive_bar_Link_01" type="mesh" group="0" contype="1" conaffinity="2" />
        <geom name="r_drive_bar_Link_coacd_col_02" mesh="legcoacd_r_drive_bar_Link_02" type="mesh" group="0" contype="1" conaffinity="2" />
        <geom name="r_drive_bar_Link_coacd_col_03" mesh="legcoacd_r_drive_bar_Link_03" type="mesh" group="0" contype="1" conaffinity="2" />
        <body name="r_coupler_Link" pos="0.040095 -0.0069 0.045306">
          <joint name="r_coupler_Joint" type="hinge" axis="0 -1 0" damping="1" armature="0.02" />
          <inertial pos="-0.08300337 -0.00146519 0.01330427" mass="0.02321892" fullinertia="0.00000249 0.00007107 0.00006893 -0.00000032 -0.00000125 0.00000007" />
          <geom name="r_coupler_Link_visual" type="mesh" mesh="visual_r_coupler" contype="0" conaffinity="0" group="1" />
          <site name="r_coupler_end" pos="-0.16999653 -0.0131 0.00108627" size="0.008" rgba="1 0.5 0 1" />
          <geom name="r_coupler_Link_coacd_col_00" mesh="legcoacd_r_coupler_Link_00" type="mesh" group="0" contype="1" conaffinity="2" />
          <geom name="r_coupler_Link_coacd_col_01" mesh="legcoacd_r_coupler_Link_01" type="mesh" group="0" contype="1" conaffinity="2" />
          <geom name="r_coupler_Link_coacd_col_02" mesh="legcoacd_r_coupler_Link_02" type="mesh" group="0" contype="1" conaffinity="2" />
          <geom name="r_coupler_Link_coacd_col_03" mesh="legcoacd_r_coupler_Link_03" type="mesh" group="0" contype="1" conaffinity="2" />
        </body>
      </body>
    </body>
  </worldbody>
  <equality>
    <connect name="l_coupler_to_lf_calf" site1="l_coupler_end" site2="lf_coupler_closure" />
    <connect name="r_coupler_to_rf_calf" site1="r_coupler_end" site2="rf_coupler_closure" />
  </equality>
  <tendon>
    <fixed name="l_active_rod_angle" limited="true" range="0 1.509535270050" solreflimit="0.010 1" solimplimit="0.99 0.999 0.00001 0.5 2">
      <joint joint="lf0_Joint" coef="1" />
      <joint joint="l_drive_bar_Joint" coef="-1" />
    </fixed>
    <fixed name="r_active_rod_angle" limited="true" range="0 1.509535270050" solreflimit="0.010 1" solimplimit="0.99 0.999 0.00001 0.5 2">
      <joint joint="r_drive_bar_Joint" coef="1" />
      <joint joint="rf0_Joint" coef="-1" />
    </fixed>
    <spatial name="l_knee_spring" width="0.003" rgba="0.2 0.6 1 1">
      <site site="l_spring_p1" />
      <site site="l_spring_p2" />
    </spatial>
    <spatial name="r_knee_spring" width="0.003" rgba="0.2 0.6 1 1">
      <site site="r_spring_p1" />
      <site site="r_spring_p2" />
    </spatial>
  </tendon>
  <actuator>
    <motor name="lf0_torque" joint="lf0_Joint" gear="1" />
    <motor name="l_drive_bar_torque" joint="l_drive_bar_Joint" gear="1" />
    <motor name="rf0_torque" joint="rf0_Joint" gear="1" />
    <motor name="r_drive_bar_torque" joint="r_drive_bar_Joint" gear="1" />
    <motor name="l_wheel_torque" joint="l_wheel_Joint" gear="1" />
    <motor name="r_wheel_torque" joint="r_wheel_Joint" gear="1" />
  </actuator>
  <keyframe>
    <key name="standing" qpos="0 0 0.22 1 0 0 0 -0.275422946189 -1.242259649307 0 -1.592100148957 1.401266340000 0.275422946189 1.242259649307 0 1.592100148957 -1.401269410000" />
  </keyframe>
</mujoco>
